....F
======================================================================
FAIL: test_CT5 (__main__.TestPacientePaths.test_CT5)
CT5 = [1, 2, 3, 5, 7, 10]
----------------------------------------------------------------------
Traceback (most recent call last):
  File "/home/joao/BTI/6ยบ SEMESTRE/TS/fila-pronto-socorro/test/CT/test_paciente.py", line 103, in test_CT5
    with self.assertRaises(ValidacaoError):
         ~~~~~~~~~~~~~~~~~^^^^^^^^^^^^^^^^
AssertionError: ValidacaoError not raised

----------------------------------------------------------------------
Ran 5 tests in 0.002s

FAILED (failures=1)