test_registro_invalidos (__main__.TestRF1.test_registro_invalidos) ... 
  test_registro_invalidos (__main__.TestRF1.test_registro_invalidos) (cpf='111222333XX', email='maria@exemplo.com', nascimento='01/01/1990') ... FAIL
  test_registro_invalidos (__main__.TestRF1.test_registro_invalidos) (cpf='12345678909', email='maria@exemplo.com', nascimento='31/13/2020') ... FAIL
test_registro_valido (__main__.TestRF1.test_registro_valido) ... ok

======================================================================
FAIL: test_registro_invalidos (__main__.TestRF1.test_registro_invalidos) (cpf='111222333XX', email='maria@exemplo.com', nascimento='01/01/1990')
----------------------------------------------------------------------
Traceback (most recent call last):
  File "/home/joao/BTI/6ยบ SEMESTRE/TS/fila-pronto-socorro/test/test_RF1.py", line 32, in test_registro_invalidos
    with self.assertRaises(ValidacaoError) as cm:
         ~~~~~~~~~~~~~~~~~^^^^^^^^^^^^^^^^
AssertionError: ValidacaoError not raised

======================================================================
FAIL: test_registro_invalidos (__main__.TestRF1.test_registro_invalidos) (cpf='12345678909', email='maria@exemplo.com', nascimento='31/13/2020')
----------------------------------------------------------------------
Traceback (most recent call last):
  File "/home/joao/BTI/6ยบ SEMESTRE/TS/fila-pronto-socorro/test/test_RF1.py", line 32, in test_registro_invalidos
    with self.assertRaises(ValidacaoError) as cm:
         ~~~~~~~~~~~~~~~~~^^^^^^^^^^^^^^^^
AssertionError: ValidacaoError not raised

----------------------------------------------------------------------
Ran 2 tests in 0.004s

FAILED (failures=2)